Workbook

Sheet 2014
A1: Tabel C.1: Totaal netto belastbaar inkomen en belasting per aangifte en per gemeente
A2: Aantal aangiften per klasse van het totaal netto belastbaar inkomen, totaal netto belastbaar inkomen, gemiddelde waarden, spreidingsmaten, asymmetrie en belasting
A3: Inkomstenjaar 2014
A6: Administratieve Eenheid | B6: Aantal aangiften met nul totaal netto belastbaar inkomen | C6: Aantal aangiften (zonder nul-inkomen) | J6: Aantal inwoners | K6: Totaal netto belastbaar inkomen | L6: Gemiddelde waarden | O6: Spreidingsmaten | Q6: Interkwartiele assymmetrie | R6: Welvaartsindex | S6: Staatsbelasting | T6: Gemeente en agglommeratie belasting | U6: Totale belasting
C7: Totaal | D7: < 10.000 EUR | E7: vanaf 10.001 tem 20.000 EUR | F7: vanaf 20.001 tem 30.000 EUR | G7: vanaf 30.001 tem 40.000 EUR | H7: vanaf 40.001 tem 50.000 EUR | I7: meer dan 50.000 EUR | L7: Gemiddeld inkomen per aangifte | M7: Mediaan inkomen per aangifte | N7: Gemiddeld inkomen per inwoner | O7: Interkwartiel verschil | P7: Interkwartiele coëfficiënt
A8: België | B8: 569497 | C8: 6261830 | D8: 849652 | E8: 1720666 | F8: 1364640 | G8: 814252 | H8: 477670 | I8: 1034950 | J8: 11209044 | K8: 198215231886 | L8: 31655 | M8: 23742 | N8: 17684 | O8: 24703 | P8: 104 | Q8: 24 | R8: 100 | S8: 42520475519 | T8: 3145839558 | U8: 45666315077
A9: Vlaams Gewest | B9: 228142 | C9: 3642974 | D9: 445083 | E9: 910598 | F9: 818936 | G9: 499405 | H9: 296101 | I9: 672851 | J9: 6444127 | K9: 122107486161 | L9: 33519 | M9: 25423 | N9: 18949 | O9: 26104 | P9: 103 | Q9: 25 | R9: 107 | S9: 27105874747 | T9: 1944917874 | U9: 29050792622
A10: Waals Gewest | B10: 205754 | C10: 2022079 | D10: 290968 | E10: 611118 | F10: 429439 | G10: 249400 | H10: 145822 | I10: 295332 | J10: 3589744 | K10: 59844207343 | L10: 29595 | M10: 22212 | N10: 16671 | O10: 22918 | P10: 103 | Q10: 27 | R10: 94 | S10: 11958599030 | T10: 941786131 | U10: 12900385161
A11: Duitstalige Gemeenschap | B11: 3881 | C11: 42316 | D11: 5704 | E11: 11542 | F11: 9883 | G11: 5685 | H11: 3461 | I11: 6041 | J11: 76328 | K11: 1290109186 | L11: 30488 | M11: 23458 | N11: 16902 | O11: 22973 | P11: 98 | Q11: 23 | R11: 96 | S11: 183379283 | T11: 15625432 | U11: 199004715
A12: Brussels Hoofdstedelijk Gewest | B12: 135601 | C12: 596777 | D12: 113601 | E12: 198950 | F12: 116265 | G12: 65447 | H12: 35747 | I12: 66767 | J12: 1175173 | K12: 16263538381 | L12: 27252 | M12: 19044 | N12: 13839 | O12: 20203 | P12: 106 | Q12: 32 | R12: 78 | S12: 3456001741 | T12: 259135553 | U12: 3715137294
A13: Provincie Antwerpen | B13: 71201 | C13: 1020707 | D13: 130243 | E13: 256308 | F13: 234836 | G13: 139217 | H13: 80287 | I13: 179816 | J13: 1813282 | K13: 33536819274 | L13: 32856 | M13: 24956 | N13: 18495 | O13: 25167 | P13: 101 | Q13: 24 | R13: 105 | S13: 7379122613 | T13: 527875157 | U13: 7906997770
A14: Arrondissement Antwerpen | B14: 49224 | C14: 576121 | D14: 78889 | E14: 148216 | F14: 133194 | G14: 76416 | H14: 43081 | I14: 96325 | J14: 1027342 | K14: 18609498611 | L14: 32301 | M14: 24197 | N14: 18114 | O14: 24443 | P14: 101 | Q14: 23 | R14: 102 | S14: 4106833157 | T14: 289820901 | U14: 4396654058
A15: Aartselaar | B15: 374 | C15: 8032 | D15: 896 | E15: 1447 | F15: 1822 | G15: 1187 | H15: 706 | I15: 1974 | J15: 14157 | K15: 329146977 | L15: 40979 | M15: 28929 | N15: 23250 | O15: 31264 | P15: 108 | Q15: 30 | R15: 131 | S15: 81240419 | T15: 3975348 | U15: 85215767
A16: Antwerpen | B16: 33379 | C16: 286590 | D16: 42166 | E16: 87856 | F16: 67020 | G16: 36653 | H16: 19074 | I16: 33821 | J16: 513570 | K16: 8019636468 | L16: 27983 | M16: 21694 | N16: 15615 | O16: 20268 | P16: 93 | Q16: 22 | R16: 88 | S16: 1630427369 | T16: 130591662 | U16: 1761019031
A17: Boechout | B17: 427 | C17: 7195 | D17: 1056 | E17: 1392 | F17: 1551 | G17: 912 | H17: 555 | I17: 1729 | J17: 12792 | K17: 274902077 | L17: 38207 | M17: 27179 | N17: 21490 | O17: 33077 | P17: 122 | Q17: 31 | R17: 122 | S17: 69192965 | T17: 5021823 | U17: 74214789
A18: Boom | B18: 447 | C18: 9882 | D18: 1212 | E18: 2710 | F18: 2398 | G18: 1361 | H18: 783 | I18: 1418 | J18: 17559 | K18: 297055849 | L18: 30060 | M18: 23794 | N18: 16918 | O18: 22102 | P18: 93 | Q18: 23 | R18: 96 | S18: 61344886 | T18: 5137917 | U18: 66482803
A19: Borsbeek | B19: 260 | C19: 6090 | D19: 733 | E19: 1413 | F19: 1545 | G19: 911 | H19: 494 | I19: 994 | J19: 10465 | K19: 196170346 | L19: 32212 | M19: 25558 | N19: 18745 | O19: 23347 | P19: 91 | Q19: 20 | R19: 106 | S19: 43337030 | T19: 2983730 | U19: 46320761
... A553: Heers | B553: 200 | C553: 4102 | D553: 424 | E553: 1189 | F553: 956 | G553: 531 | H553: 329 | I553: 673 | J553: 7237 | K553: 127045171 | L553: 30972 | M553: 24188 | N553: 17555 | O553: 23598 | P553: 98 | Q553: 29 | R553: 99 | S553: 25243788 | T553: 1866068 | U553: 27109856
A554: Herstappe | B554: * | C554: 51 | D554: 22 | F554: 29 | J554: 86 | K554: 1771579 | L554: 34737 | M554: 24255 | N554: 20600 | O554: 33479 | P554: 138 | Q554: 39 | R554: 116 | S554: 355050 | T554: 16578 | U554: 371628
A555: Hoeselt | B555: 231 | C555: 5471 | D555: 616 | E555: 1409 | F555: 1288 | G555: 722 | H555: 416 | I555: 1020 | J555: 9608 | K555: 175311520 | L555: 32044 | M555: 25297 | N555: 18246 | O555: 25491 | P555: 101 | Q555: 26 | R555: 103 | S555: 36340017 | T555: 3076331 | U555: 39416348
A556: Kortessem | B556: 226 | C556: 4735 | D556: 513 | E556: 1139 | F556: 1071 | G556: 648 | H556: 409 | I556: 955 | J556: 8380 | K556: 161941373 | L556: 34201 | M556: 26500 | N556: 19325 | O556: 27494 | P556: 104 | Q556: 25 | R556: 109 | S556: 35684890 | T556: 2998467 | U556: 38683356
A557: Lanaken | B557: 1362 | C557: 14589 | D557: 1805 | E557: 3913 | F557: 3336 | G557: 1985 | H557: 1206 | I557: 2344 | J557: 25731 | K557: 476051317 | L557: 32631 | M557: 24315 | N557: 18501 | O557: 24351 | P557: 100 | Q557: 24 | R557: 105 | S557: 73482352 | T557: 6259990 | U557: 79742342
A558: Riemst | B558: 623 | C558: 9115 | D558: 1018 | E558: 2348 | F558: 2161 | G558: 1257 | H558: 783 | I558: 1548 | J558: 16539 | K558: 291346121 | L558: 31963 | M558: 25249 | N558: 17616 | O558: 24442 | P558: 97 | Q558: 25 | R558: 100 | S558: 51988464 | T558: 4971650 | U558: 56960115
A559: Tongeren | B559: 998 | C559: 18040 | D559: 2006 | E559: 5235 | F559: 4106 | G559: 2395 | H559: 1399 | I559: 2899 | J559: 30677 | K559: 562124670 | L559: 31160 | M559: 24031 | N559: 18324 | O559: 23641 | P559: 98 | Q559: 25 | R559: 104 | S559: 115597592 | T559: 9792309 | U559: 125389901
A560: Wellen | B560: 171 | C560: 4142 | D560: 398 | E560: 1064 | F560: 923 | G560: 623 | H560: 369 | I560: 765 | J560: 7423 | K560: 137351374 | L560: 33161 | M560: 26464 | N560: 18503 | O560: 25583 | P560: 97 | Q560: 25 | R560: 105 | S560: 28772732 | T560: 2204346 | U560: 30977078
A561: Maasmechelen | B561: 1302 | C561: 20844 | D561: 2634 | E561: 6255 | F561: 5207 | G561: 2747 | H561: 1515 | I561: 2486 | J561: 37609 | K561: 598396781 | L561: 28708 | M561: 22568 | N561: 15911 | O561: 20004 | P561: 89 | Q561: 20 | R561: 90 | S561: 96403816 | T561: 8423023 | U561: 104826838
A562: Voeren | B562: * | C562: 2294 | D562: 931 | F562: 1363 | J562: 4080 | K562: 69127516 | L562: 30134 | M562: 23445 | N562: 16943 | O562: 23908 | P562: 102 | Q562: 22 | R562: 96 | S562: 11164629 | T562: 1016745 | U562: 12181374
A563: Provincie Luxemburg | B563: 14856 | C563: 149498 | D563: 21468 | E563: 38484 | F563: 31176 | G563: 19485 | H563: 12360 | I563: 26525 | J563: 278748 | K563: 4759688712 | L563: 31838 | M563: 24384 | N563: 17075 | O563: 26817 | P563: 110 | Q563: 24 | R563: 97 | S563: 656960460 | T563: 48513427 | U563: 705473887
A564: Arrondissement Aarlen | B564: 4270 | C564: 31100 | D564: 4375 | E564: 6102 | F564: 6049 | G564: 4383 | H564: 2878 | I564: 7313 | J564: 60656 | K564: 1176625072 | L564: 37834 | M564: 28143 | N564: 19398 | O564: 32436 | P564: 115 | Q564: 23 | R564: 110 | S564: 98194184 | T564: 6825384 | U564: 105019568
A565: Aarlen | B565: 2179 | C565: 15268 | D565: 2167 | E565: 3039 | F565: 2888 | G565: 2094 | H565: 1304 | I565: 3776 | J565: 29016 | K565: 591327857 | L565: 38730 | M565: 28211 | N565: 20379 | O565: 34380 | P565: 122 | Q565: 25 | R565: 115 | S565: 57123488 | T565: 3974310 | U565: 61097798
A566: Attert | B566: 324 | C566: 2494 | D566: 358 | E566: 354 | F566: 397 | G566: 288 | H566: 213 | I566: 884 | J566: 5370 | K566: 122656338 | L566: 49181 | M566: 34229 | N566: 22841 | O566: 46458 | P566: 136 | Q566: 28 | R566: 129 | S566: 9495015 | T566: 636373 | U566: 10131388
A567: Aubange | B567: 1166 | C567: 8296 | D567: 1192 | E567: 1804 | F567: 1792 | G567: 1303 | H567: 851 | I567: 1354 | J567: 16427 | K567: 263427890 | L567: 31754 | M567: 26101 | N567: 16036 | O567: 26184 | P567: 100 | Q567: 16 | R567: 91 | S567: 18179046 | T567: 1276583 | U567: 19455628
A568: Martelange | B568: 108 | C568: 919 | D568: 102 | E568: 224 | F568: 189 | G568: 140 | H568: 80 | I568: 184 | J568: 1770 | K568: 30729275 | L568: 33438 | M568: 26047 | N568: 17361 | O568: 27803 | P568: 107 | Q568: 24 | R568: 98 | S568: 2683604 | T568: 187089 | U568: 2870693
A569: Messancy | B569: 493 | C569: 4123 | D569: 556 | E569: 681 | F569: 783 | G569: 558 | H569: 430 | I569: 1115 | J569: 8073 | K569: 168483713 | L569: 40864 | M569: 30675 | N569: 20870 | O569: 35490 | P569: 116 | Q569: 24 | R569: 118 | S569: 10713031 | T569: 751029 | U569: 11464061
A570: Arrondissement Bastenaken | B570: 2350 | C570: 24975 | D570: 3618 | E570: 6653 | F570: 5303 | G570: 3268 | H570: 2151 | I570: 3982 | J570: 46857 | K570: 747470450 | L570: 29929 | M570: 23844 | N570: 15952 | O570: 25506 | P570: 107 | Q570: 24 | R570: 90 | S570: 102656443 | T570: 7730054 | U570: 110386497
A571: Bastenaken | B571: 744 | C571: 8207 | D571: 1288 | E571: 2116 | F571: 1705 | G571: 1094 | H571: 685 | I571: 1319 | J571: 15405 | K571: 247073087 | L571: 30105 | M571: 23831 | N571: 16038 | O571: 25734 | P571: 108 | Q571: 22 | R571: 91 | S571: 30591155 | T571: 2290725 | U571: 32881880
A572: Bertogne | B572: 125 | C572: 1752 | D572: 223 | E572: 436 | F572: 381 | G572: 226 | H572: 157 | I572: 329 | J572: 3431 | K572: 55691713 | L572: 31788 | M572: 25681 | N572: 16232 | O572: 27600 | P572: 107 | Q572: 24 | R572: 92 | S572: 7638215 | T572: 451393 | U572: 8089608
A573: Fauvillers | B573: 107 | C573: 1109 | D573: 133 | E573: 263 | F573: 200 | G573: 160 | H573: 113 | I573: 240 | J573: 2209 | K573: 38548331 | L573: 34760 | M573: 27497 | N573: 17451 | O573: 29974 | P573: 109 | Q573: 20 | R573: 99 | S573: 4113209 | T573: 243660 | U573: 4356869
A574: Houffalize | B574: 163 | C574: 2904 | D574: 398 | E574: 808 | F574: 647 | G574: 399 | H574: 247 | I574: 405 | J574: 5176 | K574: 83852239 | L574: 28875 | M574: 23349 | N574: 16200 | O574: 23438 | P574: 100 | Q574: 23 | R574: 92 | S574: 13045524 | T574: 908381 | U574: 13953905
... A654: Viroinval | B654: 353 | C654: 3531 | D654: 506 | E654: 1330 | F654: 796 | G654: 401 | H654: 191 | I654: 307 | J654: 5811 | K654: 85483251 | L654: 24209 | M654: 19112 | N654: 14711 | O654: 16661 | P654: 87 | Q654: 33 | R654: 83 | S654: 14448047 | T654: 1218733 | U654: 15666780
...

Sheet 2015
A1: Tabel C.1: Totaal netto belastbaar inkomen en belasting per aangifte en per gemeente
A2: Aantal aangiften per klasse van het totaal netto belastbaar inkomen, totaal netto belastbaar inkomen, gemiddelde waarden, spreidingsmaten, asymmetrie en belasting
A3: Inkomstenjaar 2015
A6: Administratieve Eenheid | B6: Aantal aangiften met nul totaal netto belastbaar inkomen | C6: Aantal aangiften (zonder nul-inkomen) | J6: Aantal inwoners | K6: Totaal netto belastbaar inkomen | L6: Gemiddelde waarden | O6: Spreidingsmaten | Q6: Interkwartiele assymmetrie | R6: Welvaartsindex | S6: Staatsbelasting | T6: Gemeente en agglommeratie belasting | U6: Totale belasting
C7: Totaal | D7: < 10.000 EUR | E7: vanaf 10.001 tem 20.000 EUR | F7: vanaf 20.001 tem 30.000 EUR | G7: vanaf 30.001 tem 40.000 EUR | H7: vanaf 40.001 tem 50.000 EUR | I7: meer dan 50.000 EUR | L7: Gemiddeld inkomen per aangifte | M7: Mediaan inkomen per aangifte | N7: Gemiddeld inkomen per inwoner | O7: Interkwartiel verschil | P7: Interkwartiele coëfficiënt
A8: België | B8: 590240 | C8: 6289750 | D8: 852717 | E8: 1717200 | F8: 1376213 | G8: 824402 | H8: 481382 | I8: 1037836 | J8: 11267910 | K8: 199414435623 | L8: 31705 | M8: 23773 | N8: 17698 | O8: 24596 | P8: 103 | Q8: 25 | R8: 100 | S8: 42804910337 | T8: 3168848029 | U8: 45973758367
A9: Vlaams Gewest | B9: 231543 | C9: 3666095 | D9: 447007 | E9: 912494 | F9: 826951 | G9: 506481 | H9: 298555 | I9: 674607 | J9: 6477804 | K9: 122885871653 | L9: 33520 | M9: 25412 | N9: 18970 | O9: 25942 | P9: 102 | Q9: 25 | R9: 107 | S9: 27256864561 | T9: 1957149441 | U9: 29214014001
A10: Waals Gewest | B10: 218513 | C10: 2025071 | D10: 291261 | E10: 606301 | F10: 432421 | G10: 252369 | H10: 146845 | I10: 295874 | J10: 3602216 | K10: 60098318063 | L10: 29677 | M10: 22302 | N10: 16684 | O10: 22816 | P10: 102 | Q10: 27 | R10: 94 | S10: 12043781678 | T10: 949503343 | U10: 12993285021
A11: Duitstalige Gemeenschap | B11: 3840 | C11: 42619 | D11: 5795 | E11: 11552 | F11: 10013 | G11: 5693 | H11: 3447 | I11: 6119 | J11: 76645 | K11: 1310510750 | L11: 30749 | M11: 23506 | N11: 17098 | O11: 22783 | P11: 97 | Q11: 23 | R11: 97 | S11: 184523433 | T11: 15871554 | U11: 200394987
A12: Brussels Hoofdstedelijk Gewest | B12: 140184 | C12: 598584 | D12: 114449 | E12: 198405 | F12: 116841 | G12: 65552 | H12: 35982 | I12: 67355 | J12: 1187890 | K12: 16430245908 | L12: 27449 | M12: 19088 | N12: 13831 | O12: 20214 | P12: 106 | Q12: 32 | R12: 78 | S12: 3504264098 | T12: 262195246 | U12: 3766459344
A13: Provincie Antwerpen | B13: 72385 | C13: 1028714 | D13: 131095 | E13: 257518 | F13: 237041 | G13: 141076 | H13: 80698 | I13: 181286 | J13: 1824136 | K13: 33865550770 | L13: 32920 | M13: 24942 | N13: 18565 | O13: 25071 | P13: 101 | Q13: 24 | R13: 105 | S13: 7451429748 | T13: 532994393 | U13: 7984424141
A14: Arrondissement Antwerpen | B14: 49400 | C14: 580709 | D14: 79362 | E14: 148945 | F14: 134649 | G14: 77126 | H14: 43422 | I14: 97205 | J14: 1033674 | K14: 18788787144 | L14: 32355 | M14: 24195 | N14: 18177 | O14: 24405 | P14: 101 | Q14: 23 | R14: 103 | S14: 4148566430 | T14: 292874729 | U14: 4441441159
A15: Aartselaar | B15: 371 | C15: 8094 | D15: 918 | E15: 1446 | F15: 1841 | G15: 1185 | H15: 730 | I15: 1974 | J15: 14262 | K15: 321778620 | L15: 39755 | M15: 28837 | N15: 22562 | O15: 31086 | P15: 108 | Q15: 30 | R15: 127 | S15: 79730667 | T15: 3943538 | U15: 83674205
A16: Antwerpen | B16: 33091 | C16: 288485 | D16: 42626 | E16: 88225 | F16: 67681 | G16: 36742 | H16: 19123 | I16: 34088 | J16: 517042 | K16: 8111517824 | L16: 28118 | M16: 21679 | N16: 15688 | O16: 20159 | P16: 93 | Q16: 23 | R16: 89 | S16: 1649059963 | T16: 131523023 | U16: 1780582985
A17: Boechout | B17: 442 | C17: 7259 | D17: 1034 | E17: 1457 | F17: 1533 | G17: 907 | H17: 595 | I17: 1733 | J17: 12844 | K17: 277592146 | L17: 38241 | M17: 27334 | N17: 21613 | O17: 32718 | P17: 120 | Q17: 30 | R17: 122 | S17: 70101493 | T17: 5096736 | U17: 75198229
A18: Boom | B18: 495 | C18: 9940 | D18: 1198 | E18: 2741 | F18: 2398 | G18: 1397 | H18: 793 | I18: 1413 | J18: 17737 | K18: 298573115 | L18: 30038 | M18: 23721 | N18: 16833 | O18: 21733 | P18: 92 | Q18: 24 | R18: 95 | S18: 61398665 | T18: 5154193 | U18: 66552858
A19: Borsbeek | B19: 295 | C19: 6117 | D19: 681 | E19: 1505 | F19: 1499 | G19: 920 | H19: 509 | I19: 1003 | J19: 10540 | K19: 201609042 | L19: 32959 | M19: 25568 | N19: 19128 | O19: 23394 | P19: 91 | Q19: 21 | R19: 108 | S19: 44323123 | T19: 3054170 | U19: 47377293
... A553: Heers | B553: 209 | C553: 4067 | D553: 423 | E553: 1132 | F553: 949 | G553: 550 | H553: 365 | I553: 648 | J553: 7205 | K553: 126556113 | L553: 31118 | M553: 24746 | N553: 17565 | O553: 23969 | P553: 97 | Q553: 27 | R553: 99 | S553: 25154817 | T553: 1860210 | U553: 27015027
A554: Herstappe | B554: * | C554: 52 | D554: 21 | F554: 31 | J554: 89 | K554: 1746649 | L554: 33589 | M554: 22786 | N554: 19625 | O554: 28720 | P554: 126 | Q554: 53 | R554: 111 | S554: 360004 | T554: 17091 | U554: 377095
A555: Hoeselt | B555: 252 | C555: 5463 | D555: 605 | E555: 1399 | F555: 1242 | G555: 796 | H555: 423 | I555: 998 | J555: 9643 | K555: 178588782 | L555: 32691 | M555: 25650 | N555: 18520 | O555: 25110 | P555: 98 | Q555: 22 | R555: 105 | S555: 36669777 | T555: 3110893 | U555: 39780669
A556: Kortessem | B556: 194 | C556: 4760 | D556: 530 | E556: 1143 | F556: 1082 | G556: 643 | H556: 421 | I556: 941 | J556: 8359 | K556: 161974299 | L556: 34028 | M556: 26498 | N556: 19377 | O556: 27702 | P556: 105 | Q556: 25 | R556: 109 | S556: 35445821 | T556: 2984317 | U556: 38430138
A557: Lanaken | B557: 1290 | C557: 14765 | D557: 1892 | E557: 3901 | F557: 3345 | G557: 2082 | H557: 1244 | I557: 2301 | J557: 25793 | K557: 470059882 | L557: 31836 | M557: 24337 | N557: 18224 | O557: 24027 | P557: 99 | Q557: 22 | R557: 103 | S557: 73122790 | T557: 6268648 | U557: 79391439
A558: Riemst | B558: 558 | C558: 9213 | D558: 1047 | E558: 2381 | F558: 2183 | G558: 1313 | H558: 758 | I558: 1531 | J558: 16572 | K558: 288892630 | L558: 31357 | M558: 25004 | N558: 17433 | O558: 23778 | P558: 95 | Q558: 25 | R558: 99 | S558: 51062205 | T558: 4899865 | U558: 55962070
A559: Tongeren | B559: 987 | C559: 18108 | D559: 2054 | E559: 5239 | F559: 4073 | G559: 2465 | H559: 1454 | I559: 2823 | J559: 30720 | K559: 561304868 | L559: 30998 | M559: 24106 | N559: 18272 | O559: 23426 | P559: 97 | Q559: 23 | R559: 103 | S559: 114171204 | T559: 9687475 | U559: 123858679
A560: Wellen | B560: 180 | C560: 4151 | D560: 416 | E560: 1035 | F560: 941 | G560: 604 | H560: 391 | I560: 764 | J560: 7374 | K560: 137411346 | L560: 33103 | M560: 26326 | N560: 18635 | O560: 25897 | P560: 98 | Q560: 26 | R560: 105 | S560: 28672666 | T560: 2199191 | U560: 30871857
A561: Maasmechelen | B561: 1218 | C561: 20939 | D561: 2639 | E561: 6155 | F561: 5301 | G561: 2890 | H561: 1586 | I561: 2368 | J561: 37696 | K561: 584668888 | L561: 27922 | M561: 22781 | N561: 15510 | O561: 19852 | P561: 87 | Q561: 19 | R561: 88 | S561: 93566665 | T561: 8270901 | U561: 101837567
A562: Voeren | B562: * | C562: 2300 | D562: 941 | F562: 1359 | J562: 4099 | K562: 69663044 | L562: 30288 | M562: 23355 | N562: 16995 | O562: 23152 | P562: 99 | Q562: 23 | R562: 96 | S562: 11434977 | T562: 1057798 | U562: 12492776
A563: Provincie Luxemburg | B563: 15682 | C563: 151202 | D563: 21547 | E563: 38217 | F563: 32011 | G563: 19805 | H563: 12685 | I563: 26937 | J563: 280327 | K563: 4838629208 | L563: 32001 | M563: 24552 | N563: 17261 | O563: 26807 | P563: 109 | Q563: 24 | R563: 98 | S563: 662352320 | T563: 49101222 | U563: 711453543
A564: Arrondissement Aarlen | B564: 4009 | C564: 31959 | D564: 4387 | E564: 6097 | F564: 6443 | G564: 4515 | H564: 2970 | I564: 7547 | J564: 61180 | K564: 1215128866 | L564: 38021 | M564: 28280 | N564: 19862 | O564: 32198 | P564: 114 | Q564: 24 | R564: 112 | S564: 98585518 | T564: 6873060 | U564: 105458578
A565: Aarlen | B565: 2041 | C565: 15651 | D565: 2185 | E565: 3018 | F565: 3047 | G565: 2143 | H565: 1357 | I565: 3901 | J565: 29274 | K565: 611979373 | L565: 39102 | M565: 28316 | N565: 20905 | O565: 34202 | P565: 121 | Q565: 26 | R565: 118 | S565: 56694689 | T565: 3950194 | U565: 60644883
A566: Attert | B566: 342 | C566: 2526 | D566: 351 | E566: 349 | F566: 422 | G566: 301 | H566: 207 | I566: 896 | J566: 5411 | K566: 124983733 | L566: 49479 | M566: 34375 | N566: 23098 | O566: 46590 | P566: 136 | Q566: 31 | R566: 131 | S566: 10060856 | T566: 700398 | U566: 10761254
A567: Aubange | B567: 1072 | C567: 8656 | D567: 1213 | E567: 1834 | F567: 1979 | G567: 1344 | H567: 886 | I567: 1400 | J567: 16646 | K567: 274465327 | L567: 31708 | M567: 26093 | N567: 16488 | O567: 25570 | P567: 98 | Q567: 17 | R567: 93 | S567: 18195374 | T567: 1272921 | U567: 19468295
A568: Martelange | B568: 94 | C568: 952 | D568: 107 | E568: 241 | F568: 199 | G568: 134 | H568: 93 | I568: 178 | J568: 1767 | K568: 30849761 | L568: 32405 | M568: 25556 | N568: 17459 | O568: 27779 | P568: 109 | Q568: 24 | R568: 99 | S568: 2413408 | T568: 167676 | U568: 2581084
A569: Messancy | B569: 460 | C569: 4174 | D569: 531 | E569: 655 | F569: 796 | G569: 593 | H569: 427 | I569: 1172 | J569: 8082 | K569: 172850673 | L569: 41411 | M569: 31708 | N569: 21387 | O569: 36094 | P569: 114 | Q569: 24 | R569: 121 | S569: 11221191 | T569: 781872 | U569: 12003062
A570: Arrondissement Bastenaken | B570: 2831 | C570: 25385 | D570: 3644 | E570: 6636 | F570: 5501 | G570: 3341 | H570: 2177 | I570: 4086 | J570: 47319 | K570: 763001948 | L570: 30057 | M570: 23983 | N570: 16125 | O570: 25397 | P570: 106 | Q570: 24 | R570: 91 | S570: 104212818 | T570: 7835906 | U570: 112048723
A571: Bastenaken | B571: 723 | C571: 8360 | D571: 1278 | E571: 2134 | F571: 1800 | G571: 1103 | H571: 695 | I571: 1350 | J571: 15580 | K571: 250752036 | L571: 29994 | M571: 23740 | N571: 16094 | O571: 25436 | P571: 107 | Q571: 24 | R571: 91 | S571: 31027657 | T571: 2327910 | U571: 33355567
A572: Bertogne | B572: 113 | C572: 1766 | D572: 229 | E572: 410 | F572: 379 | G572: 232 | H572: 176 | I572: 340 | J572: 3483 | K572: 58365142 | L572: 33049 | M572: 26170 | N572: 16757 | O572: 28423 | P572: 109 | Q572: 24 | R572: 95 | S572: 8070748 | T572: 477703 | U572: 8548451
A573: Fauvillers | B573: 89 | C573: 1133 | D573: 150 | E573: 249 | F573: 224 | G573: 163 | H573: 106 | I573: 241 | J573: 2237 | K573: 39521330 | L573: 34882 | M573: 26905 | N573: 17667 | O573: 29753 | P573: 111 | Q573: 24 | R573: 100 | S573: 4108787 | T573: 243589 | U573: 4352376
A574: Houffalize | B574: 181 | C574: 2941 | D574: 400 | E574: 823 | F574: 661 | G574: 398 | H574: 253 | I574: 406 | J574: 5177 | K574: 85644380 | L574: 29121 | M574: 23559 | N574: 16543 | O574: 23387 | P574: 99 | Q574: 21 | R574: 93 | S574: 13185784 | T574: 911866 | U574: 14097650
... A654: Viroinval | B654: 523 | C654: 3532 | D654: 500 | E654: 1357 | F654: 804 | G654: 376 | H654: 200 | I654: 295 | J654: 5806 | K654: 84971931 | L654: 24058 | M654: 19178 | N654: 14635 | O654: 16046 | P654: 84 | Q654: 31 | R654: 83 | S654: 14338682 | T654: 1215842 | U654: 15554524
...

Sheet 2016
A1: Tabel C.1: Totaal netto belastbaar inkomen en belasting per aangifte en per gemeente
A2: Aantal aangiften per klasse van het totaal netto belastbaar inkomen, totaal netto belastbaar inkomen, gemiddelde waarden, spreidingsmaten, asymmetrie en belasting
A3: Inkomstenjaar 2016
A6: Administratieve Eenheid | B6: Aantal aangiften met nul totaal netto belastbaar inkomen | C6: Aantal aangiften (zonder nul-inkomen) | J6: Aantal inwoners | K6: Totaal netto belastbaar inkomen | L6: Gemiddelde waarden | O6: Spreidingsmaten | Q6: Interkwartiele assymmetrie | R6: Welvaartsindex | S6: Staatsbelasting | T6: Gemeente en agglommeratie belasting | U6: Totale belasting
C7: Totaal | D7: < 10.000 EUR | E7: vanaf 10.001 tem 20.000 EUR | F7: vanaf 20.001 tem 30.000 EUR | G7: vanaf 30.001 tem 40.000 EUR | H7: vanaf 40.001 tem 50.000 EUR | I7: meer dan 50.000 EUR | L7: Gemiddeld inkomen per aangifte | M7: Mediaan inkomen per aangifte | N7: Gemiddeld inkomen per inwoner | O7: Interkwartiel verschil | P7: Interkwartiele coëfficiënt
A8: België | B8: 589521 | C8: 6318465 | D8: 852793 | E8: 1713246 | F8: 1385333 | G8: 827636 | H8: 488192 | I8: 1051265 | J8: 11322088 | K8: 201799579114 | L8: 31938 | M8: 23773 | N8: 17824 | O8: 24584 | P8: 103 | Q8: 27 | R8: 100 | S8: 42705157890 | T8: 3125176369 | U8: 45830334259
A9: Vlaams Gewest | B9: 225998 | C9: 3688596 | D9: 449899 | E9: 907187 | F9: 833673 | G9: 510387 | H9: 303934 | I9: 683516 | J9: 6516011 | K9: 124465879416 | L9: 33743 | M9: 25401 | N9: 19102 | O9: 25923 | P9: 102 | Q9: 27 | R9: 107 | S9: 27233036530 | T9: 1953769480 | U9: 29186806010
A10: Waals Gewest | B10: 221487 | C10: 2028546 | D10: 287148 | E10: 607007 | F10: 433886 | G10: 252837 | H10: 148730 | I10: 298938 | J10: 3614473 | K10: 60674547634 | L10: 29910 | M10: 22320 | N10: 16787 | O10: 22780 | P10: 102 | Q10: 29 | R10: 94 | S10: 11952381424 | T10: 945609963 | U10: 12897991387
A11: Duitstalige Gemeenschap | B11: 3663 | C11: 42704 | D11: 5774 | E11: 11516 | F11: 9938 | G11: 5802 | H11: 3426 | I11: 6248 | J11: 76920 | K11: 1328453394 | L11: 31108 | M11: 23594 | N11: 17271 | O11: 22892 | P11: 97 | Q11: 24 | R11: 97 | S11: 182816188 | T11: 15536145 | U11: 198352333
A12: Brussels Hoofdstedelijk Gewest | B12: 142036 | C12: 601323 | D12: 115746 | E12: 199052 | F12: 117774 | G12: 64412 | H12: 35528 | I12: 68811 | J12: 1191604 | K12: 16659152064 | L12: 27704 | M12: 19072 | N12: 13980 | O12: 20043 | P12: 105 | Q12: 32 | R12: 78 | S12: 3519739936 | T12: 225796927 | U12: 3745536862
A13: Provincie Antwerpen | B13: 70228 | C13: 1035226 | D13: 132320 | E13: 255986 | F13: 239184 | G13: 141386 | H13: 81958 | I13: 184392 | J13: 1836030 | K13: 34319446843 | L13: 33152 | M13: 24949 | N13: 18692 | O13: 25156 | P13: 101 | Q13: 26 | R13: 105 | S13: 7450924247 | T13: 533120087 | U13: 7984044334
A14: Arrondissement Antwerpen | B14: 47923 | C14: 584051 | D14: 80214 | E14: 148252 | F14: 135853 | G14: 76899 | H14: 43911 | I14: 98922 | J14: 1039943 | K14: 19036619827 | L14: 32594 | M14: 24179 | N14: 18305 | O14: 24523 | P14: 101 | Q14: 24 | R14: 103 | S14: 4152900969 | T14: 292708956 | U14: 4445609924
A15: Aartselaar | B15: 332 | C15: 8132 | D15: 909 | E15: 1450 | F15: 1879 | G15: 1163 | H15: 768 | I15: 1963 | J15: 14222 | K15: 323548210 | L15: 39787 | M15: 28858 | N15: 22750 | O15: 30602 | P15: 106 | Q15: 31 | R15: 128 | S15: 79247036 | T15: 3929249 | U15: 83176284
A16: Antwerpen | B16: 32089 | C16: 290027 | D16: 43377 | E16: 87777 | F16: 68279 | G16: 36582 | H16: 19213 | I16: 34799 | J16: 520504 | K16: 8181492956 | L16: 28209 | M16: 21688 | N16: 15718 | O16: 20016 | P16: 92 | Q16: 25 | R16: 88 | S16: 1637673046 | T16: 132041690 | U16: 1769714736
A17: Boechout | B17: 414 | C17: 7372 | D17: 1045 | E17: 1427 | F17: 1599 | G17: 941 | H17: 615 | I17: 1745 | J17: 12908 | K17: 289339590 | L17: 39248 | M17: 27425 | N17: 22416 | O17: 32090 | P17: 117 | Q17: 30 | R17: 126 | S17: 71561510 | T17: 5228872 | U17: 76790382
A18: Boom | B18: 503 | C18: 9986 | D18: 1230 | E18: 2731 | F18: 2408 | G18: 1381 | H18: 810 | I18: 1426 | J18: 17788 | K18: 300549632 | L18: 30097 | M18: 23722 | N18: 16896 | O18: 21855 | P18: 92 | Q18: 25 | R18: 95 | S18: 60794817 | T18: 4767531 | U18: 65562347
A19: Borsbeek | B19: 293 | C19: 6108 | D19: 689 | E19: 1455 | F19: 1545 | G19: 930 | H19: 466 | I19: 1023 | J19: 10581 | K19: 197907531 | L19: 32401 | M19: 25461 | N19: 18704 | O19: 23315 | P19: 92 | Q19: 20 | R19: 105 | S19: 43017471 | T19: 2974657 | U19: 45992128
... A553: Heers | B553: 199 | C553: 4090 | D553: 423 | E553: 1145 | F553: 963 | G553: 541 | H553: 365 | I553: 653 | J553: 7225 | K553: 129547078 | L553: 31674 | M553: 24394 | N553: 17930 | O553: 23701 | P553: 97 | Q553: 30 | R553: 101 | S553: 25362183 | T553: 1884858 | U553: 27247040
A554: Herstappe | B554: * | C554: 53 | D554: 53 | J554: 89 | K554: 1722221 | L554: 32495 | M554: 25258 | N554: 19351 | O554: 25988 | P554: 103 | Q554: 30 | R554: 109 | S554: 326380 | T554: 15408 | U554: 341788
A555: Hoeselt | B555: 221 | C555: 5524 | D555: 630 | E555: 1400 | F555: 1288 | G555: 801 | H555: 444 | I555: 961 | J555: 9709 | K555: 176391378 | L555: 31932 | M555: 25069 | N555: 18168 | O555: 24361 | P555: 97 | Q555: 26 | R555: 102 | S555: 35124682 | T555: 3054213 | U555: 38178895
A556: Kortessem | B556: 188 | C556: 4724 | D556: 511 | E556: 1126 | F556: 1064 | G556: 663 | H556: 414 | I556: 946 | J556: 8359 | K556: 160040017 | L556: 33878 | M556: 26718 | N556: 19146 | O556: 27099 | P556: 101 | Q556: 25 | R556: 107 | S556: 34334563 | T556: 2903330 | U556: 37237893
A557: Lanaken | B557: 1169 | C557: 14788 | D557: 1891 | E557: 3894 | F557: 3377 | G557: 2096 | H557: 1219 | I557: 2311 | J557: 25800 | K557: 472158342 | L557: 31928 | M557: 24299 | N557: 18301 | O557: 23662 | P557: 97 | Q557: 24 | R557: 103 | S557: 71611363 | T557: 6106895 | U557: 77718258
A558: Riemst | B558: 559 | C558: 9211 | D558: 1036 | E558: 2402 | F558: 2188 | G558: 1317 | H558: 783 | I558: 1485 | J558: 16592 | K558: 288364213 | L558: 31307 | M558: 24970 | N558: 17380 | O558: 23473 | P558: 94 | Q558: 25 | R558: 98 | S558: 49578643 | T558: 4486282 | U558: 54064924
A559: Tongeren | B559: 893 | C559: 18203 | D559: 2043 | E559: 5294 | F559: 4108 | G559: 2502 | H559: 1458 | I559: 2798 | J559: 30865 | K559: 569580792 | L559: 31290 | M559: 23884 | N559: 18454 | O559: 23144 | P559: 97 | Q559: 26 | R559: 104 | S559: 112226796 | T559: 9576625 | U559: 121803421
A560: Wellen | B560: 173 | C560: 4191 | D560: 402 | E560: 1032 | F560: 976 | G560: 627 | H560: 396 | I560: 758 | J560: 7406 | K560: 139081032 | L560: 33186 | M560: 26305 | N560: 18780 | O560: 25242 | P560: 96 | Q560: 27 | R560: 105 | S560: 28452035 | T560: 2195549 | U560: 30647584
A561: Maasmechelen | B561: 1225 | C561: 21025 | D561: 2662 | E561: 6275 | F561: 5293 | G561: 3040 | H561: 1583 | I561: 2172 | J561: 37813 | K561: 573818270 | L561: 27292 | M561: 22593 | N561: 15175 | O561: 19320 | P561: 86 | Q561: 20 | R561: 85 | S561: 87175993 | T561: 7799610 | U561: 94975603
A562: Voeren | B562: * | C562: 2313 | D562: 2313 | J562: 4129 | K562: 69879866 | L562: 30212 | M562: 23280 | N562: 16924 | O562: 23090 | P562: 99 | Q562: 28 | R562: 95 | S562: 11116513 | T562: 1042708 | U562: 12159221
A563: Provincie Luxemburg | B563: 16081 | C563: 152089 | D563: 21719 | E563: 38663 | F563: 31777 | G563: 19993 | H563: 12911 | I563: 27026 | J563: 281972 | K563: 4878676569 | L563: 32078 | M563: 24404 | N563: 17302 | O563: 26561 | P563: 109 | Q563: 27 | R563: 97 | S563: 651417263 | T563: 48579198 | U563: 699996461
A564: Arrondissement Aarlen | B564: 4907 | C564: 31899 | D564: 4484 | E564: 6332 | F564: 6253 | G564: 4461 | H564: 2914 | I564: 7455 | J564: 61899 | K564: 1207100665 | L564: 37841 | M564: 27943 | N564: 19501 | O564: 31958 | P564: 114 | Q564: 24 | R564: 109 | S564: 96717672 | T564: 6795573 | U564: 103513244
A565: Aarlen | B565: 2624 | C565: 15675 | D565: 2187 | E565: 3082 | F565: 3001 | G565: 2173 | H565: 1323 | I565: 3909 | J565: 29585 | K565: 613047521 | L565: 39110 | M565: 28336 | N565: 20722 | O565: 34161 | P565: 121 | Q565: 26 | R565: 116 | S565: 56107577 | T565: 3934579 | U565: 60042156
A566: Attert | B566: 363 | C566: 2572 | D566: 350 | E566: 383 | F566: 423 | G566: 304 | H566: 214 | I566: 898 | J566: 5491 | K566: 127010254 | L566: 49382 | M566: 33953 | N566: 23131 | O566: 45529 | P566: 134 | Q566: 31 | R566: 130 | S566: 9500702 | T566: 666162 | U566: 10166864
A567: Aubange | B567: 1320 | C567: 8501 | D567: 1231 | E567: 1939 | F567: 1852 | G567: 1273 | H567: 865 | I567: 1341 | J567: 16856 | K567: 266289500 | L567: 31324 | M567: 25494 | N567: 15798 | O567: 25451 | P567: 100 | Q567: 19 | R567: 89 | S567: 17717488 | T567: 1255954 | U567: 18973442
A568: Martelange | B568: 97 | C568: 976 | D568: 130 | E568: 243 | F568: 190 | G568: 146 | H568: 87 | I568: 180 | J568: 1814 | K568: 31097696 | L568: 31862 | M568: 25295 | N568: 17143 | O568: 27460 | P568: 109 | Q568: 25 | R568: 96 | S568: 2426111 | T568: 169925 | U568: 2596036
A569: Messancy | B569: 503 | C569: 4175 | D569: 586 | E569: 685 | F569: 787 | G569: 565 | H569: 425 | I569: 1127 | J569: 8153 | K569: 169655693 | L569: 40636 | M569: 30431 | N569: 20809 | O569: 35435 | P569: 116 | Q569: 24 | R569: 117 | S569: 10965793 | T569: 768953 | U569: 11734746
A570: Arrondissement Bastenaken | B570: 2663 | C570: 25756 | D570: 3748 | E570: 6711 | F570: 5490 | G570: 3403 | H570: 2316 | I570: 4088 | J570: 47844 | K570: 775068969 | L570: 30093 | M570: 23852 | N570: 16200 | O570: 25308 | P570: 106 | Q570: 27 | R570: 91 | S570: 102481274 | T570: 7753239 | U570: 110234513
A571: Bastenaken | B571: 741 | C571: 8510 | D571: 1337 | E571: 2133 | F571: 1808 | G571: 1135 | H571: 767 | I571: 1330 | J571: 15737 | K571: 256527761 | L571: 30144 | M571: 23776 | N571: 16301 | O571: 25309 | P571: 106 | Q571: 25 | R571: 91 | S571: 30635379 | T571: 2307051 | U571: 32942430
A572: Bertogne | B572: 126 | C572: 1769 | D572: 229 | E572: 410 | F572: 357 | G572: 246 | H572: 174 | I572: 353 | J572: 3542 | K572: 58581244 | L572: 33115 | M572: 26507 | N572: 16539 | O572: 28962 | P572: 109 | Q572: 25 | R572: 93 | S572: 7894680 | T572: 471265 | U572: 8365944
A573: Fauvillers | B573: 91 | C573: 1124 | D573: 147 | E573: 234 | F573: 223 | G573: 163 | H573: 110 | I573: 247 | J573: 2251 | K573: 39572308 | L573: 35207 | M573: 27394 | N573: 17580 | O573: 30177 | P573: 110 | Q573: 23 | R573: 99 | S573: 3964119 | T573: 237778 | U573: 4201897
A574: Houffalize | B574: 182 | C574: 2967 | D574: 397 | E574: 830 | F574: 661 | G574: 395 | H574: 266 | I574: 418 | J574: 5232 | K574: 87536182 | L574: 29503 | M574: 23486 | N574: 16731 | O574: 23337 | P574: 99 | Q574: 25 | R574: 94 | S574: 13134663 | T574: 912729 | U574: 14047392
... A654: Viroinval | B654: 457 | C654: 3517 | D654: 497 | E654: 1350 | F654: 788 | G654: 379 | H654: 215 | I654: 288 | J654: 5755 | K654: 84959856 | L654: 24157 | M654: 19149 | N654: 14763 | O654: 16067 | P654: 84 | Q654: 35 | R654: 83 | S654: 13890652 | T654: 1183685 | U654: 15074337
...

Sheet 2017
A1: Tabel C.1: Totaal netto belastbaar inkomen en belasting per aangifte en per gemeente
A2: Aantal aangiften per klasse van het totaal netto belastbaar inkomen, totaal netto belastbaar inkomen, gemiddelde waarden, spreidingsmaten, asymmetrie en belasting
A3: Inkomstenjaar 2017
A6: Administratieve Eenheid | B6: Aantal aangiften met nul totaal netto belastbaar inkomen | C6: Aantal aangiften (zonder nul-inkomen) | J6: Aantal inwoners | K6: Totaal netto belastbaar inkomen | L6: Gemiddelde waarden | O6: Spreidingsmaten | Q6: Interkwartiele assymmetrie | R6: Welvaartsindex | S6: Staatsbelasting | T6: Gemeente en agglommeratie belasting | U6: Totale belasting
C7: Totaal | D7: < 10.000 EUR | E7: vanaf 10.001 tem 20.000 EUR | F7: vanaf 20.001 tem 30.000 EUR | G7: vanaf 30.001 tem 40.000 EUR | H7: vanaf 40.001 tem 50.000 EUR | I7: meer dan 50.000 EUR | L7: Gemiddeld inkomen per aangifte | M7: Mediaan inkomen per aangifte | N7: Gemiddeld inkomen per inwoner | O7: Interkwartiel verschil | P7: Interkwartiele coëfficiënt
A8: België | B8: 547750 | C8: 6371585 | D8: 843990 | E8: 1660522 | F8: 1401770 | G8: 856131 | H8: 504379 | I8: 1104793 | J8: 11376070 | K8: 208538121504 | L8: 32729 | M8: 24345 | N8: 18331 | O8: 25086 | P8: 103 | Q8: 27 | R8: 100 | S8: 44476161497 | T8: 3246748522 | U8: 47722910020
A9: Vlaams Gewest | B9: 207412 | C9: 3719171 | D9: 445534 | E9: 873034 | F9: 839622 | G9: 528746 | H9: 313806 | I9: 718429 | J9: 6552967 | K9: 128676748404 | L9: 34598 | M9: 26019 | N9: 19636 | O9: 26483 | P9: 102 | Q9: 27 | R9: 107 | S9: 28397703573 | T9: 2031075852 | U9: 30428779425
A10: Waals Gewest | B10: 206483 | C10: 2042084 | D10: 283970 | E10: 589630 | F10: 440770 | G10: 260117 | H10: 153317 | I10: 314280 | J10: 3624377 | K10: 62632739351 | L10: 30671 | M10: 22849 | N10: 17281 | O10: 23234 | P10: 102 | Q10: 30 | R10: 94 | S10: 12419150555 | T10: 983304651 | U10: 13402455206
A11: Duitstalige Gemeenschap | B11: 3122 | C11: 43157 | D11: 5670 | E11: 11168 | F11: 10012 | G11: 5943 | H11: 3643 | I11: 6721 | J11: 77185 | K11: 1384225674 | L11: 32074 | M11: 24275 | N11: 17934 | O11: 23780 | P11: 98 | Q11: 25 | R11: 98 | S11: 192316724 | T11: 16266836 | U11: 208583560
A12: Brussels Hoofdstedelijk Gewest | B12: 133855 | C12: 610330 | D12: 114486 | E12: 197858 | F12: 121378 | G12: 67268 | H12: 37256 | I12: 72084 | J12: 1198726 | K12: 17228633749 | L12: 28228 | M12: 19540 | N12: 14372 | O12: 20319 | P12: 104 | Q12: 32 | R12: 78 | S12: 3659307369 | T12: 232368020 | U12: 3891675388
A13: Provincie Antwerpen | B13: 63266 | C13: 1043813 | D13: 131231 | E13: 246603 | F13: 240762 | G13: 146466 | H13: 85041 | I13: 193710 | J13: 1847486 | K13: 35455722651 | L13: 33968 | M13: 25548 | N13: 19191 | O13: 25738 | P13: 101 | Q13: 26 | R13: 105 | S13: 7769663914 | T13: 555091632 | U13: 8324755546
A14: Arrondissement Antwerpen | B14: 43089 | C14: 588179 | D14: 79242 | E14: 142971 | F14: 136866 | G14: 79406 | H14: 45816 | I14: 103878 | J14: 1045593 | K14: 19628495865 | L14: 33372 | M14: 24772 | N14: 18773 | O14: 25129 | P14: 101 | Q14: 25 | R14: 102 | S14: 4319725871 | T14: 304392519 | U14: 4624118391
A15: Aartselaar | B15: 341 | C15: 8225 | D15: 930 | E15: 1395 | F15: 1888 | G15: 1175 | H15: 793 | I15: 2044 | J15: 14304 | K15: 337059915 | L15: 40980 | M15: 29497 | N15: 23564 | O15: 31436 | P15: 107 | Q15: 30 | R15: 129 | S15: 84163415 | T15: 4157387 | U15: 88320803
A16: Antwerpen | B16: 29158 | C16: 291991 | D16: 42800 | E16: 85263 | F16: 69157 | G16: 37787 | H16: 20339 | I16: 36645 | J16: 523248 | K16: 8414375998 | L16: 28817 | M16: 22216 | N16: 16081 | O16: 20498 | P16: 92 | Q16: 25 | R16: 88 | S16: 1699545319 | T16: 137091412 | U16: 1836636732
A17: Boechout | B17: 432 | C17: 7428 | D17: 1049 | E17: 1373 | F17: 1578 | G17: 975 | H17: 594 | I17: 1859 | J17: 13120 | K17: 295933460 | L17: 39840 | M17: 28056 | N17: 22556 | O17: 33448 | P17: 119 | Q17: 32 | R17: 123 | S17: 74296204 | T17: 5421999 | U17: 79718203
A18: Boom | B18: 472 | C18: 10115 | D18: 1248 | E18: 2614 | F18: 2459 | G18: 1466 | H18: 825 | I18: 1503 | J18: 17970 | K18: 311473325 | L18: 30793 | M18: 24268 | N18: 17333 | O18: 22250 | P18: 92 | Q18: 24 | R18: 95 | S18: 63488996 | T18: 4981625 | U18: 68470621
A19: Borsbeek | B19: 292 | C19: 6130 | D19: 702 | E19: 1402 | F19: 1507 | G19: 957 | H19: 527 | I19: 1035 | J19: 10685 | K19: 201619966 | L19: 32891 | M19: 26021 | N19: 18869 | O19: 23917 | P19: 92 | Q19: 20 | R19: 103 | S19: 43196058 | T19: 2988065 | U19: 46184123
... A553: Heers | B553: 200 | C553: 4129 | D553: 420 | E553: 1040 | F553: 1005 | G553: 588 | H553: 362 | I553: 714 | J553: 7290 | K553: 132478519 | L553: 32085 | M553: 25448 | N553: 18173 | O553: 24315 | P553: 96 | Q553: 27 | R553: 99 | S553: 26422785 | T553: 1964702 | U553: 28387487
A554: Herstappe | B554: * | C554: 51 | D554: 20 | F554: 31 | J554: 88 | K554: 1704506 | L554: 33422 | M554: 23294 | N554: 19369 | O554: 26591 | P554: 114 | Q554: 46 | R554: 106 | S554: 328164 | T554: 15339 | U554: 343503
A555: Hoeselt | B555: 184 | C555: 5555 | D555: 645 | E555: 1347 | F555: 1282 | G555: 816 | H555: 442 | I555: 1023 | J555: 9685 | K555: 180822603 | L555: 32551 | M555: 25613 | N555: 18670 | O555: 25318 | P555: 99 | Q555: 26 | R555: 102 | S555: 36590473 | T555: 3129498 | U555: 39719971
A556: Kortessem | B556: 170 | C556: 4795 | D556: 502 | E556: 1071 | F556: 1082 | G556: 725 | H556: 428 | I556: 987 | J556: 8446 | K556: 167249739 | L556: 34880 | M556: 27336 | N556: 19802 | O556: 27315 | P556: 100 | Q556: 24 | R556: 108 | S556: 36091319 | T556: 3052091 | U556: 39143409
A557: Lanaken | B557: 904 | C557: 14728 | D557: 1712 | E557: 3786 | F557: 3473 | G557: 2154 | H557: 1227 | I557: 2376 | J557: 25818 | K557: 482852559 | L557: 32785 | M557: 24883 | N557: 18702 | O557: 23632 | P557: 95 | Q557: 24 | R557: 102 | S557: 74690081 | T557: 6428674 | U557: 81118755
A558: Riemst | B558: 503 | C558: 9309 | D558: 996 | E558: 2265 | F558: 2244 | G558: 1392 | H558: 785 | I558: 1627 | J558: 16665 | K558: 301974870 | L558: 32439 | M558: 25940 | N558: 18120 | O558: 24048 | P558: 93 | Q558: 24 | R558: 99 | S558: 52947217 | T558: 4794184 | U558: 57741401
A559: Tongeren | B559: 841 | C559: 18296 | D559: 2019 | E559: 5058 | F559: 4206 | G559: 2636 | H559: 1461 | I559: 2916 | J559: 31032 | K559: 576781003 | L559: 31525 | M559: 24356 | N559: 18587 | O559: 23303 | P559: 96 | Q559: 26 | R559: 101 | S559: 115144307 | T559: 9833295 | U559: 124977602
A560: Wellen | B560: 148 | C560: 4215 | D560: 406 | E560: 993 | F560: 958 | G560: 653 | H560: 403 | I560: 802 | J560: 7402 | K560: 143201897 | L560: 33974 | M560: 26849 | N560: 19346 | O560: 26044 | P560: 97 | Q560: 27 | R560: 106 | S560: 29593344 | T560: 2284188 | U560: 31877532
A561: Maasmechelen | B561: 1155 | C561: 21175 | D561: 2536 | E561: 6045 | F561: 5458 | G561: 3146 | H561: 1665 | I561: 2325 | J561: 38193 | K561: 595578935 | L561: 28127 | M561: 23178 | N561: 15594 | O561: 19589 | P561: 85 | Q561: 20 | R561: 85 | S561: 91628818 | T561: 8224772 | U561: 99853590
A562: Voeren | B562: * | C562: 2370 | D562: 896 | F562: 1474 | J562: 4160 | K562: 75571425 | L562: 31887 | M562: 24311 | N562: 18166 | O562: 24772 | P562: 102 | Q562: 27 | R562: 99 | S562: 12334675 | T562: 1142023 | U562: 13476698
A563: Provincie Luxemburg | B563: 13319 | C563: 153625 | D563: 21393 | E563: 37495 | F563: 32253 | G563: 20437 | H563: 13158 | I563: 28889 | J563: 283227 | K563: 5072907269 | L563: 33021 | M563: 25038 | N563: 17911 | O563: 27360 | P563: 109 | Q563: 27 | R563: 98 | S563: 672021481 | T563: 50049699 | U563: 722071181
A564: Arrondissement Aarlen | B564: 4406 | C564: 32247 | D564: 4443 | E564: 5983 | F564: 6225 | G564: 4511 | H564: 3067 | I564: 8018 | J564: 62202 | K564: 1267860831 | L564: 39317 | M564: 29062 | N564: 20383 | O564: 33545 | P564: 115 | Q564: 24 | R564: 111 | S564: 98689640 | T564: 6921263 | U564: 105610904
A565: Aarlen | B565: 2190 | C565: 15863 | D565: 2203 | E565: 2916 | F565: 3030 | G565: 2134 | H565: 1426 | I565: 4154 | J565: 29733 | K565: 640411084 | L565: 40371 | M565: 29279 | N565: 21539 | O565: 35736 | P565: 122 | Q565: 27 | R565: 117 | S565: 57033148 | T565: 4012405 | U565: 61045553
A566: Attert | B566: 370 | C566: 2622 | D566: 364 | E566: 373 | F566: 412 | G566: 323 | H566: 224 | I566: 926 | J566: 5537 | K566: 132310374 | L566: 50462 | M566: 34775 | N566: 23896 | O566: 47072 | P566: 135 | Q566: 29 | R566: 130 | S566: 9397017 | T566: 661228 | U566: 10058245
A567: Aubange | B567: 1267 | C567: 8622 | D567: 1228 | E567: 1820 | F567: 1841 | G567: 1336 | H567: 873 | I567: 1524 | J567: 16927 | K567: 282943232 | L567: 32816 | M567: 26388 | N567: 16715 | O567: 26959 | P567: 102 | Q567: 20 | R567: 91 | S567: 18686971 | T567: 1321317 | U567: 20008288
A568: Martelange | B568: 97 | C568: 933 | D568: 109 | E568: 205 | F568: 186 | G568: 145 | H568: 96 | I568: 192 | J568: 1820 | K568: 32251548 | L568: 34568 | M568: 27637 | N568: 17721 | O568: 29392 | P568: 106 | Q568: 23 | R568: 97 | S568: 2456027 | T568: 172625 | U568: 2628652
A569: Messancy | B569: 482 | C569: 4207 | D569: 539 | E569: 669 | F569: 756 | G569: 573 | H569: 448 | I569: 1222 | J569: 8185 | K569: 179944595 | L569: 42773 | M569: 32059 | N569: 21985 | O569: 36601 | P569: 114 | Q569: 23 | R569: 120 | S569: 11116479 | T569: 753687 | U569: 11870166
A570: Arrondissement Bastenaken | B570: 1821 | C570: 26030 | D570: 3698 | E570: 6514 | F570: 5627 | G570: 3412 | H570: 2328 | I570: 4451 | J570: 48183 | K570: 805891955 | L570: 30960 | M570: 24537 | N570: 16726 | O570: 26056 | P570: 106 | Q570: 27 | R570: 91 | S570: 105997017 | T570: 7964325 | U570: 113961342
A571: Bastenaken | B571: 665 | C571: 8673 | D571: 1282 | E571: 2129 | F571: 1891 | G571: 1129 | H571: 779 | I571: 1463 | J571: 15894 | K571: 270343210 | L571: 31171 | M571: 24525 | N571: 17009 | O571: 26054 | P571: 106 | Q571: 25 | R571: 93 | S571: 31797325 | T571: 2387380 | U571: 34184705
A572: Bertogne | B572: 104 | C572: 1815 | D572: 237 | E572: 404 | F572: 355 | G572: 262 | H572: 183 | I572: 374 | J572: 3579 | K572: 60714365 | L572: 33451 | M572: 26789 | N572: 16964 | O572: 29802 | P572: 111 | Q572: 28 | R572: 93 | S572: 8113302 | T572: 485580 | U572: 8598882
A573: Fauvillers | B573: 102 | C573: 1122 | D573: 142 | E573: 218 | F573: 224 | G573: 166 | H573: 108 | I573: 264 | J573: 2253 | K573: 40533845 | L573: 36126 | M573: 28822 | N573: 17991 | O573: 32198 | P573: 112 | Q573: 21 | R573: 98 | S573: 4138772 | T573: 246268 | U573: 4385040
A574: Houffalize | B574: 175 | C574: 2961 | D574: 407 | E574: 782 | F574: 657 | G574: 393 | H574: 249 | I574: 473 | J574: 5222 | K574: 89211052 | L574: 30129 | M574: 24176 | N574: 17084 | O574: 24299 | P574: 101 | Q574: 25 | R574: 93 | S574: 13360298 | T574: 928207 | U574: 14288505
... A654: Viroinval | B654: 299 | C654: 3480 | D654: 426 | E654: 1340 | F654: 785 | G654: 411 | H654: 213 | I654: 305 | J654: 5731 | K654: 86789716 | L654: 24940 | M654: 19790 | N654: 15144 | O654: 16532 | P654: 84 | Q654: 35 | R654: 83 | S654: 14326826 | T654: 1224998 | U654: 15551824
...

Sheet NIS-codes
A1: Administratieve Eenheid | B1: NIS code
A2: ’s Gravenbrakel | B2: 55004
A3: Aalst (Aalst) | B3: 41002
A4: Aalter | B4: 44001
A5: Aarlen | B5: 81001
A6: Aarschot | B6: 24001
A7: Aartselaar | B7: 11001
A8: Aat | B8: 51004
A9: Affligem | B9: 23105
A10: Aiseau-Presles | B10: 52074
A11: Alken | B11: 73001
A12: Alveringem | B12: 38002
A13: Amay | B13: 61003
... A648: Zwijndrecht | B648: 11056

Sheet INSTRUCTIES
A1: gebruik onderstaande voorvoegsels voor de onderwerpencodes
A2: v
A3: vp
A4: kubus
A5: vs
A8: maak deze onderwerpen aan
A9: aangiften_min_10d
A10: aangiften_10t20d
A11: aangiften_20t30d
A12: aangiften_30t40d
A13: aangiften_40t50d
A14: aangiften_50d_plus
A15: aangiften_tot | C15: hier een formuleonderwerp van maken (optelsom van 6 voorgaande onderwerpen)
A16: mediaan | C16: niet-aggregeerbaar --> dus ook inlezen voor arr, provincies, gewest
A17: welvaartsindex | C17: niet-aggregeerbaar --> dus ook inlezen voor arr, provincies, gewest
A19: Let op: het gaat nog over de oude gemeenten (gemeente2018)
A20: niet aggreggeerbare gegevens inlezen voor zowel gemeente als gemeente2018
A21: niet aggreggeerbare gegevens inlezen voor zowel arrondissementen als arrondissementen2018
A23: Maak afgeleide percentages
A25: Zet in een mapje in de themaboom TESTMAP > Opleiding > Jouw naam

Sheet onderwerpen
A1: Onderwerpcode | B1: Naam | C1: Beschrijving | D1: Meer informatie | E1: Eenheid | F1: Bron | G1: Formule | H1: Datatype | I1: Vrij tekstveld | J1: Afronding
B2: aangiften < 10.000 EUR | I2: opleiding
B3: aangiften 10.001 - 20.000 EUR | I3: opleiding
B4: aangiften 20.001 - 30.000 EUR | I4: opleiding
B5: aangiften 30.001 - 40.000 EUR | I5: opleiding
B6: aangiften 40.001 - 50.000 EUR | I6: opleiding
B7: aangiften > 50.000 EUR | I7: opleiding
B8: mediaaninkomen per aangifte | I8: opleiding
B9: welvaartsindex | I9: opleiding
B10: totaal aangiften | I10: opleiding

Sheet UPLOAD
A1: period | B1: geolevel | C1: geoitem | D1: _aangiften_min_10d | E1: _aangiften_10t20d | F1: _aangiften_20t30d | G1: _aangiften_30t40d | H1: _aangiften_40t50d | I1: _aangiften_50d_plus | J1: _mediaan | K1: _welvaartsindex

Sheet VOORBEELD vert. zoeken
A1: Tabel C.1: Totaal netto belastbaar inkomen en belasting per aangifte en per gemeente
A2: Aantal aangiften per klasse van het totaal netto belastbaar inkomen, totaal netto belastbaar inkomen, gemiddelde waarden, spreidingsmaten, asymmetrie en belasting
A3: Inkomstenjaar 2014
A6: Administratieve Eenheid | C6: Aantal aangiften met nul totaal netto belastbaar inkomen | D6: Aantal aangiften (zonder nul-inkomen) | K6: Aantal inwoners | L6: Totaal netto belastbaar inkomen | M6: Gemiddelde waarden | P6: Spreidingsmaten | R6: Interkwartiele assymmetrie | S6: Welvaartsindex | T6: Staatsbelasting | U6: Gemeente en agglommeratie belasting | V6: Totale belasting
D7: Totaal | E7: < 10.000 EUR | F7: vanaf 10.001 tem 20.000 EUR | G7: vanaf 20.001 tem 30.000 EUR | H7: vanaf 30.001 tem 40.000 EUR | I7: vanaf 40.001 tem 50.000 EUR | J7: meer dan 50.000 EUR | M7: Gemiddeld inkomen per aangifte | N7: Mediaan inkomen per aangifte | O7: Gemiddeld inkomen per inwoner | P7: Interkwartiel verschil | Q7: Interkwartiele coëfficiënt
A8: België | B8: =VLOOKUP(A8,'NIS-codes'!$A$2:$B$648,2,FALSE) -> 1000 | C8: 569497 | D8: 6261830 | E8: 849652 | F8: 1720666 | G8: 1364640 | H8: 814252 | I8: 477670 | J8: 1034950 | K8: 11209044 | L8: 198215231886 | M8: 31655 | N8: 23742 | O8: 17684 | P8: 24703 | Q8: 104 | R8: 24 | S8: 100 | T8: 42520475519 | U8: 3145839558 | V8: 45666315077
A9: Vlaams Gewest | B9: =VLOOKUP(A9,'NIS-codes'!$A$2:$B$648,2,FALSE) -> 2000 | C9: 228142 | D9: 3642974 | E9: 445083 | F9: 910598 | G9: 818936 | H9: 499405 | I9: 296101 | J9: 672851 | K9: 6444127 | L9: 122107486161 | M9: 33519 | N9: 25423 | O9: 18949 | P9: 26104 | Q9: 103 | R9: 25 | S9: 107 | T9: 27105874747 | U9: 1944917874 | V9: 29050792622
A10: Waals Gewest | B10: =VLOOKUP(A10,'NIS-codes'!$A$2:$B$648,2,FALSE) -> 3000 | C10: 205754 | D10: 2022079 | E10: 290968 | F10: 611118 | G10: 429439 | H10: 249400 | I10: 145822 | J10: 295332 | K10: 3589744 | L10: 59844207343 | M10: 29595 | N10: 22212 | O10: 16671 | P10: 22918 | Q10: 103 | R10: 27 | S10: 94 | T10: 11958599030 | U10: 941786131 | V10: 12900385161
A11: Duitstalige Gemeenschap | B11: =VLOOKUP(A11,'NIS-codes'!$A$2:$B$648,2,FALSE) -> 3001 | C11: 3881 | D11: 42316 | E11: 5704 | F11: 11542 | G11: 9883 | H11: 5685 | I11: 3461 | J11: 6041 | K11: 76328 | L11: 1290109186 | M11: 30488 | N11: 23458 | O11: 16902 | P11: 22973 | Q11: 98 | R11: 23 | S11: 96 | T11: 183379283 | U11: 15625432 | V11: 199004715
A12: Brussels Hoofdstedelijk Gewest | B12: =VLOOKUP(A12,'NIS-codes'!$A$2:$B$648,2,FALSE) -> 4000 | C12: 135601 | D12: 596777 | E12: 113601 | F12: 198950 | G12: 116265 | H12: 65447 | I12: 35747 | J12: 66767 | K12: 1175173 | L12: 16263538381 | M12: 27252 | N12: 19044 | O12: 13839 | P12: 20203 | Q12: 106 | R12: 32 | S12: 78 | T12: 3456001741 | U12: 259135553 | V12: 3715137294
A13: Provincie Antwerpen | B13: =VLOOKUP(A13,'NIS-codes'!$A$2:$B$648,2,FALSE) -> 10000 | C13: 71201 | D13: 1020707 | E13: 130243 | F13: 256308 | G13: 234836 | H13: 139217 | I13: 80287 | J13: 179816 | K13: 1813282 | L13: 33536819274 | M13: 32856 | N13: 24956 | O13: 18495 | P13: 25167 | Q13: 101 | R13: 24 | S13: 105 | T13: 7379122613 | U13: 527875157 | V13: 7906997770
A14: Arrondissement Antwerpen | B14: =VLOOKUP(A14,'NIS-codes'!$A$2:$B$648,2,FALSE) -> 11000 | C14: 49224 | D14: 576121 | E14: 78889 | F14: 148216 | G14: 133194 | H14: 76416 | I14: 43081 | J14: 96325 | K14: 1027342 | L14: 18609498611 | M14: 32301 | N14: 24197 | O14: 18114 | P14: 24443 | Q14: 101 | R14: 23 | S14: 102 | T14: 4106833157 | U14: 289820901 | V14: 4396654058
A15: Aartselaar | B15: =VLOOKUP(A15,'NIS-codes'!$A$2:$B$648,2,FALSE) -> 11001 | C15: 374 | D15: 8032 | E15: 896 | F15: 1447 | G15: 1822 | H15: 1187 | I15: 706 | J15: 1974 | K15: 14157 | L15: 329146977 | M15: 40979 | N15: 28929 | O15: 23250 | P15: 31264 | Q15: 108 | R15: 30 | S15: 131 | T15: 81240419 | U15: 3975348 | V15: 85215767
A16: Antwerpen | B16: =VLOOKUP(A16,'NIS-codes'!$A$2:$B$648,2,FALSE) -> 11002 | C16: 33379 | D16: 286590 | E16: 42166 | F16: 87856 | G16: 67020 | H16: 36653 | I16: 19074 | J16: 33821 | K16: 513570 | L16: 8019636468 | M16: 27983 | N16: 21694 | O16: 15615 | P16: 20268 | Q16: 93 | R16: 22 | S16: 88 | T16: 1630427369 | U16: 130591662 | V16: 1761019031
A17: Boechout | B17: =VLOOKUP(A17,'NIS-codes'!$A$2:$B$648,2,FALSE) -> 11004 | C17: 427 | D17: 7195 | E17: 1056 | F17: 1392 | G17: 1551 | H17: 912 | I17: 555 | J17: 1729 | K17: 12792 | L17: 274902077 | M17: 38207 | N17: 27179 | O17: 21490 | P17: 33077 | Q17: 122 | R17: 31 | S17: 122 | T17: 69192965 | U17: 5021823 | V17: 74214789
A18: Boom | B18: =VLOOKUP(A18,'NIS-codes'!$A$2:$B$648,2,FALSE) -> 11005 | C18: 447 | D18: 9882 | E18: 1212 | F18: 2710 | G18: 2398 | H18: 1361 | I18: 783 | J18: 1418 | K18: 17559 | L18: 297055849 | M18: 30060 | N18: 23794 | O18: 16918 | P18: 22102 | Q18: 93 | R18: 23 | S18: 96 | T18: 61344886 | U18: 5137917 | V18: 66482803
A19: Borsbeek | B19: =VLOOKUP(A19,'NIS-codes'!$A$2:$B$648,2,FALSE) -> 11007 | C19: 260 | D19: 6090 | E19: 733 | F19: 1413 | G19: 1545 | H19: 911 | I19: 494 | J19: 994 | K19: 10465 | L19: 196170346 | M19: 32212 | N19: 25558 | O19: 18745 | P19: 23347 | Q19: 91 | R19: 20 | S19: 106 | T19: 43337030 | U19: 2983730 | V19: 46320761
... A553: Heers | B553: =VLOOKUP(A553,'NIS-codes'!$A$2:$B$648,2,FALSE) -> 73022 | C553: 200 | D553: 4102 | E553: 424 | F553: 1189 | G553: 956 | H553: 531 | I553: 329 | J553: 673 | K553: 7237 | L553: 127045171 | M553: 30972 | N553: 24188 | O553: 17555 | P553: 23598 | Q553: 98 | R553: 29 | S553: 99 | T553: 25243788 | U553: 1866068 | V553: 27109856
A554: Herstappe | B554: =VLOOKUP(A554,'NIS-codes'!$A$2:$B$648,2,FALSE) -> 73028 | C554: * | D554: 51 | E554: 22 | G554: 29 | K554: 86 | L554: 1771579 | M554: 34737 | N554: 24255 | O554: 20600 | P554: 33479 | Q554: 138 | R554: 39 | S554: 116 | T554: 355050 | U554: 16578 | V554: 371628
A555: Hoeselt | B555: =VLOOKUP(A555,'NIS-codes'!$A$2:$B$648,2,FALSE) -> 73032 | C555: 231 | D555: 5471 | E555: 616 | F555: 1409 | G555: 1288 | H555: 722 | I555: 416 | J555: 1020 | K555: 9608 | L555: 175311520 | M555: 32044 | N555: 25297 | O555: 18246 | P555: 25491 | Q555: 101 | R555: 26 | S555: 103 | T555: 36340017 | U555: 3076331 | V555: 39416348
A556: Kortessem | B556: =VLOOKUP(A556,'NIS-codes'!$A$2:$B$648,2,FALSE) -> 73040 | C556: 226 | D556: 4735 | E556: 513 | F556: 1139 | G556: 1071 | H556: 648 | I556: 409 | J556: 955 | K556: 8380 | L556: 161941373 | M556: 34201 | N556: 26500 | O556: 19325 | P556: 27494 | Q556: 104 | R556: 25 | S556: 109 | T556: 35684890 | U556: 2998467 | V556: 38683356
A557: Lanaken | B557: =VLOOKUP(A557,'NIS-codes'!$A$2:$B$648,2,FALSE) -> 73042 | C557: 1362 | D557: 14589 | E557: 1805 | F557: 3913 | G557: 3336 | H557: 1985 | I557: 1206 | J557: 2344 | K557: 25731 | L557: 476051317 | M557: 32631 | N557: 24315 | O557: 18501 | P557: 24351 | Q557: 100 | R557: 24 | S557: 105 | T557: 73482352 | U557: 6259990 | V557: 79742342
A558: Riemst | B558: =VLOOKUP(A558,'NIS-codes'!$A$2:$B$648,2,FALSE) -> 73066 | C558: 623 | D558: 9115 | E558: 1018 | F558: 2348 | G558: 2161 | H558: 1257 | I558: 783 | J558: 1548 | K558: 16539 | L558: 291346121 | M558: 31963 | N558: 25249 | O558: 17616 | P558: 24442 | Q558: 97 | R558: 25 | S558: 100 | T558: 51988464 | U558: 4971650 | V558: 56960115
A559: Tongeren | B559: =VLOOKUP(A559,'NIS-codes'!$A$2:$B$648,2,FALSE) -> 73083 | C559: 998 | D559: 18040 | E559: 2006 | F559: 5235 | G559: 4106 | H559: 2395 | I559: 1399 | J559: 2899 | K559: 30677 | L559: 562124670 | M559: 31160 | N559: 24031 | O559: 18324 | P559: 23641 | Q559: 98 | R559: 25 | S559: 104 | T559: 115597592 | U559: 9792309 | V559: 125389901
A560: Wellen | B560: =VLOOKUP(A560,'NIS-codes'!$A$2:$B$648,2,FALSE) -> 73098 | C560: 171 | D560: 4142 | E560: 398 | F560: 1064 | G560: 923 | H560: 623 | I560: 369 | J560: 765 | K560: 7423 | L560: 137351374 | M560: 33161 | N560: 26464 | O560: 18503 | P560: 25583 | Q560: 97 | R560: 25 | S560: 105 | T560: 28772732 | U560: 2204346 | V560: 30977078
A561: Maasmechelen | B561: =VLOOKUP(A561,'NIS-codes'!$A$2:$B$648,2,FALSE) -> 73107 | C561: 1302 | D561: 20844 | E561: 2634 | F561: 6255 | G561: 5207 | H561: 2747 | I561: 1515 | J561: 2486 | K561: 37609 | L561: 598396781 | M561: 28708 | N561: 22568 | O561: 15911 | P561: 20004 | Q561: 89 | R561: 20 | S561: 90 | T561: 96403816 | U561: 8423023 | V561: 104826838
A562: Voeren | B562: =VLOOKUP(A562,'NIS-codes'!$A$2:$B$648,2,FALSE) -> 73109 | C562: * | D562: 2294 | E562: 931 | G562: 1363 | K562: 4080 | L562: 69127516 | M562: 30134 | N562: 23445 | O562: 16943 | P562: 23908 | Q562: 102 | R562: 22 | S562: 96 | T562: 11164629 | U562: 1016745 | V562: 12181374
A563: Provincie Luxemburg | B563: =VLOOKUP(A563,'NIS-codes'!$A$2:$B$648,2,FALSE) -> 80000 | C563: 14856 | D563: 149498 | E563: 21468 | F563: 38484 | G563: 31176 | H563: 19485 | I563: 12360 | J563: 26525 | K563: 278748 | L563: 4759688712 | M563: 31838 | N563: 24384 | O563: 17075 | P563: 26817 | Q563: 110 | R563: 24 | S563: 97 | T563: 656960460 | U563: 48513427 | V563: 705473887
A564: Arrondissement Aarlen | B564: =VLOOKUP(A564,'NIS-codes'!$A$2:$B$648,2,FALSE) -> 81000 | C564: 4270 | D564: 31100 | E564: 4375 | F564: 6102 | G564: 6049 | H564: 4383 | I564: 2878 | J564: 7313 | K564: 60656 | L564: 1176625072 | M564: 37834 | N564: 28143 | O564: 19398 | P564: 32436 | Q564: 115 | R564: 23 | S564: 110 | T564: 98194184 | U564: 6825384 | V564: 105019568
A565: Aarlen | B565: =VLOOKUP(A565,'NIS-codes'!$A$2:$B$648,2,FALSE) -> 81001 | C565: 2179 | D565: 15268 | E565: 2167 | F565: 3039 | G565: 2888 | H565: 2094 | I565: 1304 | J565: 3776 | K565: 29016 | L565: 591327857 | M565: 38730 | N565: 28211 | O565: 20379 | P565: 34380 | Q565: 122 | R565: 25 | S565: 115 | T565: 57123488 | U565: 3974310 | V565: 61097798
A566: Attert | B566: =VLOOKUP(A566,'NIS-codes'!$A$2:$B$648,2,FALSE) -> 81003 | C566: 324 | D566: 2494 | E566: 358 | F566: 354 | G566: 397 | H566: 288 | I566: 213 | J566: 884 | K566: 5370 | L566: 122656338 | M566: 49181 | N566: 34229 | O566: 22841 | P566: 46458 | Q566: 136 | R566: 28 | S566: 129 | T566: 9495015 | U566: 636373 | V566: 10131388
A567: Aubange | B567: =VLOOKUP(A567,'NIS-codes'!$A$2:$B$648,2,FALSE) -> 81004 | C567: 1166 | D567: 8296 | E567: 1192 | F567: 1804 | G567: 1792 | H567: 1303 | I567: 851 | J567: 1354 | K567: 16427 | L567: 263427890 | M567: 31754 | N567: 26101 | O567: 16036 | P567: 26184 | Q567: 100 | R567: 16 | S567: 91 | T567: 18179046 | U567: 1276583 | V567: 19455628
A568: Martelange | B568: =VLOOKUP(A568,'NIS-codes'!$A$2:$B$648,2,FALSE) -> 81013 | C568: 108 | D568: 919 | E568: 102 | F568: 224 | G568: 189 | H568: 140 | I568: 80 | J568: 184 | K568: 1770 | L568: 30729275 | M568: 33438 | N568: 26047 | O568: 17361 | P568: 27803 | Q568: 107 | R568: 24 | S568: 98 | T568: 2683604 | U568: 187089 | V568: 2870693
A569: Messancy | B569: =VLOOKUP(A569,'NIS-codes'!$A$2:$B$648,2,FALSE) -> 81015 | C569: 493 | D569: 4123 | E569: 556 | F569: 681 | G569: 783 | H569: 558 | I569: 430 | J569: 1115 | K569: 8073 | L569: 168483713 | M569: 40864 | N569: 30675 | O569: 20870 | P569: 35490 | Q569: 116 | R569: 24 | S569: 118 | T569: 10713031 | U569: 751029 | V569: 11464061
A570: Arrondissement Bastenaken | B570: =VLOOKUP(A570,'NIS-codes'!$A$2:$B$648,2,FALSE) -> 82000 | C570: 2350 | D570: 24975 | E570: 3618 | F570: 6653 | G570: 5303 | H570: 3268 | I570: 2151 | J570: 3982 | K570: 46857 | L570: 747470450 | M570: 29929 | N570: 23844 | O570: 15952 | P570: 25506 | Q570: 107 | R570: 24 | S570: 90 | T570: 102656443 | U570: 7730054 | V570: 110386497
A571: Bastenaken | B571: =VLOOKUP(A571,'NIS-codes'!$A$2:$B$648,2,FALSE) -> 82003 | C571: 744 | D571: 8207 | E571: 1288 | F571: 2116 | G571: 1705 | H571: 1094 | I571: 685 | J571: 1319 | K571: 15405 | L571: 247073087 | M571: 30105 | N571: 23831 | O571: 16038 | P571: 25734 | Q571: 108 | R571: 22 | S571: 91 | T571: 30591155 | U571: 2290725 | V571: 32881880
A572: Bertogne | B572: =VLOOKUP(A572,'NIS-codes'!$A$2:$B$648,2,FALSE) -> 82005 | C572: 125 | D572: 1752 | E572: 223 | F572: 436 | G572: 381 | H572: 226 | I572: 157 | J572: 329 | K572: 3431 | L572: 55691713 | M572: 31788 | N572: 25681 | O572: 16232 | P572: 27600 | Q572: 107 | R572: 24 | S572: 92 | T572: 7638215 | U572: 451393 | V572: 8089608
A573: Fauvillers | B573: =VLOOKUP(A573,'NIS-codes'!$A$2:$B$648,2,FALSE) -> 82009 | C573: 107 | D573: 1109 | E573: 133 | F573: 263 | G573: 200 | H573: 160 | I573: 113 | J573: 240 | K573: 2209 | L573: 38548331 | M573: 34760 | N573: 27497 | O573: 17451 | P573: 29974 | Q573: 109 | R573: 20 | S573: 99 | T573: 4113209 | U573: 243660 | V573: 4356869
A574: Houffalize | B574: =VLOOKUP(A574,'NIS-codes'!$A$2:$B$648,2,FALSE) -> 82014 | C574: 163 | D574: 2904 | E574: 398 | F574: 808 | G574: 647 | H574: 399 | I574: 247 | J574: 405 | K574: 5176 | L574: 83852239 | M574: 28875 | N574: 23349 | O574: 16200 | P574: 23438 | Q574: 100 | R574: 23 | S574: 92 | T574: 13045524 | U574: 908381 | V574: 13953905
... A654: Viroinval | B654: =VLOOKUP(A654,'NIS-codes'!$A$2:$B$648,2,FALSE) -> 93090 | C654: 353 | D654: 3531 | E654: 506 | F654: 1330 | G654: 796 | H654: 401 | I654: 191 | J654: 307 | K654: 5811 | L654: 85483251 | M654: 24209 | N654: 19112 | O654: 14711 | P654: 16661 | Q654: 87 | R654: 33 | S654: 83 | T654: 14448047 | U654: 1218733 | V654: 15666780
...
